Workbook

Sheet Pivot_Analysis
A1: Customer Segment Comparison
A3: engagement_segment | B3: Count of customer_id
A4: High | B4: 755
A5: Low | B5: 7
A6: Moderate | B6: 410
A7: Very High | B7: 28
A8: Grand Total | B8: 1200
G15: Transaction Activity by Type
A20: transaction_type | B20: Count of transaction_id | C20: Average of amount
A21: Bill Payment | B21: 3467 | C21: 3290.5287
A22: Cash Withdrawal | B22: 2388 | C22: 3751.3917
A23: Credit | B23: 4419 | C23: 3508.4048
A24: Debit | B24: 7461 | C24: 3623.2945
A25: Transfer | B25: 4088 | C25: 3362.8265
A26: Grand Total | B26: 21823 | C26: 3512.401

Sheet Customer_Data
A1: customer_id | B1: age_band | C1: region | D1: relationship_years | E1: account_count | F1: account_type_count | G1: account_types | H1: transaction_count | I1: total_transaction_amount | J1: average_transaction_amount | K1: branch_visits | L1: atm_usage | M1: mobile_usage | N1: internet_usage | O1: branch_visits_was_missing | P1: atm_usage_was_missing | Q1: mobile_usage_was_missing | R1: internet_usage_was_missing | S1: service_request_count | T1: complaint_count | U1: unresolved_request_count | V1: channel_diversity | W1: total_channel_usage | X1: engagement_segment | Y1: has_complaint | Z1: has_unresolved_request | AA1: last_transaction_date | AB1: days_since_last_transaction | AC1: activity_change | AD1: declining_activity_flag
A2: CUST00001 | B2: 36-45 | C2: South | D2: 17 | E2: 1 | F2: 1 | G2: Savings | H2: 17 | I2: 38691.18 | J2: 2275.9517647058824 | K2: 2 | L2: 6 | M2: 10 | N2: 8 | O2: 0 | P2: 0 | Q2: 0 | R2: 0 | S2: 1 | T2: 0 | U2: 0 | V2: 4 | W2: 26 | X2: High | Y2: 0 | Z2: 0 | AA2: 45942 | AB2: 81 | AC2: -9 | AD2: 1
A3: CUST00002 | B3: 46-60 | C3: West | D3: 2 | E3: 1 | F3: 1 | G3: Savings | H3: 16 | I3: 29347.55 | J3: 1834.2219 | K3: 1 | L3: 5 | M3: 9 | N3: 8 | O3: 0 | P3: 0 | Q3: 0 | R3: 0 | S3: 1 | T3: 0 | U3: 0 | V3: 4 | W3: 23 | X3: High | Y3: 0 | Z3: 0 | AA3: 46016 | AB3: 7 | AC3: -2 | AD3: 1
A4: CUST00003 | B4: 60+ | C4: Central | D4: 23 | E4: 1 | F4: 1 | G4: Savings | H4: 10 | I4: 19452.99 | J4: 1945.2990000000002 | K4: 5 | L4: 9 | M4: 12 | N4: 5 | O4: 0 | P4: 0 | Q4: 0 | R4: 0 | S4: 1 | T4: 1 | U4: 0 | V4: 4 | W4: 31 | X4: Moderate | Y4: 1 | Z4: 0 | AA4: 46013 | AB4: 10 | AC4: -4 | AD4: 1
A5: CUST00004 | B5: 60+ | C5: West | D5: 10 | E5: 1 | F5: 1 | G5: Current | H5: 12 | I5: 26822.23 | J5: 2235.1858333333334 | K5: 2 | L5: 4 | M5: 8 | N5: 4 | O5: 0 | P5: 0 | Q5: 0 | R5: 0 | S5: 2 | T5: 1 | U5: 0 | V5: 4 | W5: 18 | X5: Moderate | Y5: 1 | Z5: 0 | AA5: 46006 | AB5: 17 | AC5: 2 | AD5: 0
A6: CUST00005 | B6: 26-35 | C6: West | D6: 4 | E6: 1 | F6: 1 | G6: Current | H6: 24 | I6: 65388.56 | J6: 2724.523333333333 | K6: 3 | L6: 7 | M6: 5 | N6: 7 | O6: 0 | P6: 0 | Q6: 0 | R6: 0 | S6: 1 | T6: 0 | U6: 0 | V6: 4 | W6: 22 | X6: High | Y6: 0 | Z6: 0 | AA6: 45947 | AB6: 76 | AC6: -10 | AD6: 1
A7: CUST00006 | B7: 36-45 | C7: East | D7: 8 | E7: 3 | F7: 2 | G7: Salary, Savings | H7: 18 | I7: 46448.46 | J7: 2580.47 | K7: 1 | L7: 5 | M7: 17 | N7: 3 | O7: 0 | P7: 0 | Q7: 0 | R7: 0 | S7: 2 | T7: 2 | U7: 0 | V7: 4 | W7: 26 | X7: High | Y7: 1 | Z7: 0 | AA7: 45998 | AB7: 25 | AC7: 0 | AD7: 0
A8: CUST00007 | B8: 26-35 | C8: North | D8: 10 | E8: 1 | F8: 1 | G8: Salary | H8: 23 | I8: 81250.41 | J8: 3532.6265217391306 | K8: 2 | L8: 3 | M8: 17 | N8: 6 | O8: 0 | P8: 0 | Q8: 0 | R8: 0 | S8: 0 | T8: 0 | U8: 0 | V8: 4 | W8: 28 | X8: High | Y8: 0 | Z8: 0 | AA8: 46014 | AB8: 9 | AC8: 7 | AD8: 0
A9: CUST00008 | B9: 46-60 | C9: West | D9: 12 | E9: 2 | F9: 2 | G9: Current, Fixed Deposit | H9: 20 | I9: 106335.73 | J9: 5316.7865 | K9: 2 | L9: 5 | M9: 11 | N9: 5 | O9: 0 | P9: 0 | Q9: 0 | R9: 0 | S9: 1 | T9: 0 | U9: 0 | V9: 4 | W9: 23 | X9: High | Y9: 0 | Z9: 0 | AA9: 46020 | AB9: 3 | AC9: -4 | AD9: 1
A10: CUST00009 | B10: 36-45 | C10: Central | D10: 4 | E10: 1 | F10: 1 | G10: Savings | H10: 11 | I10: 51319.19 | J10: 4665.380909090909 | K10: 2 | L10: 5 | M10: 3 | N10: 11 | O10: 0 | P10: 0 | Q10: 0 | R10: 0 | S10: 0 | T10: 0 | U10: 0 | V10: 4 | W10: 21 | X10: Moderate | Y10: 0 | Z10: 0 | AA10: 45988 | AB10: 35 | AC10: 3 | AD10: 0
A11: CUST00010 | B11: 36-45 | C11: South | D11: 8 | E11: 2 | F11: 1 | G11: Savings | H11: 7 | I11: 14222.92 | J11: 2031.8457142857144 | K11: 2 | L11: 3 | M11: 9 | N11: 5 | O11: 1 | P11: 0 | Q11: 0 | R11: 0 | S11: 2 | T11: 1 | U11: 0 | V11: 4 | W11: 19 | X11: Moderate | Y11: 1 | Z11: 0 | AA11: 45939 | AB11: 84 | AC11: -3 | AD11: 1
A12: CUST00011 | B12: 26-35 | C12: Central | D12: 22 | E12: 1 | F12: 1 | G12: Fixed Deposit | H12: 28 | I12: 158418.95 | J12: 5657.819642857144 | K12: 1 | L12: 7 | M12: 11 | N12: 7 | O12: 0 | P12: 0 | Q12: 1 | R12: 0 | S12: 0 | T12: 0 | U12: 0 | V12: 4 | W12: 26 | X12: High | Y12: 0 | Z12: 0 | AA12: 45980 | AB12: 43 | AC12: -4 | AD12: 1
A13: CUST00012 | B13: 46-60 | C13: Central | D13: 2 | E13: 1 | F13: 1 | G13: Savings | H13: 24 | I13: 150229.66 | J13: 6259.569166666667 | K13: 3 | L13: 4 | M13: 9 | N13: 4 | O13: 0 | P13: 0 | Q13: 0 | R13: 0 | S13: 1 | T13: 0 | U13: 0 | V13: 4 | W13: 20 | X13: High | Y13: 0 | Z13: 0 | AA13: 46016 | AB13: 7 | AC13: 2 | AD13: 0
A14: CUST00013 | B14: 18-25 | C14: Central | D14: 14 | E14: 1 | F14: 1 | G14: Fixed Deposit | H14: 12 | I14: 38751.770000000004 | J14: 3229.314166666667 | K14: 0 | L14: 0 | M14: 11 | N14: 6 | O14: 0 | P14: 0 | Q14: 0 | R14: 0 | S14: 1 | T14: 0 | U14: 0 | V14: 2 | W14: 17 | X14: Moderate | Y14: 0 | Z14: 0 | AA14: 45983 | AB14: 40 | AC14: 6 | AD14: 0
A15: CUST00014 | B15: 60+ | C15: West | D15: 18 | E15: 1 | F15: 1 | G15: Savings | H15: 10 | I15: 20968.61 | J15: 2096.861 | K15: 1 | L15: 8 | M15: 11 | N15: 8 | O15: 0 | P15: 0 | Q15: 0 | R15: 0 | S15: 1 | T15: 0 | U15: 0 | V15: 4 | W15: 28 | X15: Moderate | Y15: 0 | Z15: 0 | AA15: 45986 | AB15: 37 | AC15: 0 | AD15: 0
A16: CUST00015 | B16: 36-45 | C16: West | D16: 4 | E16: 3 | F16: 2 | G16: Fixed Deposit, Savings | H16: 19 | I16: 43600.47 | J16: 2294.7615789473684 | K16: 1 | L16: 4 | M16: 9 | N16: 6 | O16: 0 | P16: 0 | Q16: 0 | R16: 0 | S16: 0 | T16: 0 | U16: 0 | V16: 4 | W16: 20 | X16: High | Y16: 0 | Z16: 0 | AA16: 45988 | AB16: 35 | AC16: 1 | AD16: 0
A17: CUST00016 | B17: 26-35 | C17: West | D17: 25 | E17: 2 | F17: 1 | G17: Savings | H17: 24 | I17: 100440.70999999999 | J17: 4185.029583333333 | K17: 0 | L17: 5 | M17: 8 | N17: 12 | O17: 0 | P17: 0 | Q17: 0 | R17: 0 | S17: 2 | T17: 0 | U17: 0 | V17: 3 | W17: 25 | X17: High | Y17: 0 | Z17: 0 | AA17: 46017 | AB17: 6 | AC17: 4 | AD17: 0
A18: CUST00017 | B18: 36-45 | C18: Central | D18: 15 | E18: 2 | F18: 1 | G18: Savings | H18: 17 | I18: 35474.92 | J18: 2086.7599999999998 | K18: 3 | L18: 4 | M18: 12 | N18: 7 | O18: 0 | P18: 0 | Q18: 0 | R18: 0 | S18: 1 | T18: 1 | U18: 1 | V18: 4 | W18: 26 | X18: High | Y18: 1 | Z18: 1 | AA18: 46014 | AB18: 9 | AC18: -5 | AD18: 1
A19: CUST00018 | B19: 46-60 | C19: West | D19: 18 | E19: 2 | F19: 2 | G19: Fixed Deposit, Savings | H19: 18 | I19: 67790.64 | J19: 3766.1466666666665 | K19: 0 | L19: 5 | M19: 19 | N19: 5 | O19: 0 | P19: 1 | Q19: 0 | R19: 0 | S19: 2 | T19: 0 | U19: 0 | V19: 3 | W19: 29 | X19: High | Y19: 0 | Z19: 0 | AA19: 45986 | AB19: 37 | AC19: -10 | AD19: 1
A20: CUST00019 | B20: 18-25 | C20: Central | D20: 13 | E20: 1 | F20: 1 | G20: Savings | H20: 16 | I20: 20839.9 | J20: 1302.4938 | K20: 1 | L20: 2 | M20: 17 | N20: 8 | O20: 0 | P20: 0 | Q20: 0 | R20: 0 | S20: 0 | T20: 0 | U20: 0 | V20: 4 | W20: 28 | X20: High | Y20: 0 | Z20: 0 | AA20: 46020 | AB20: 3 | AC20: 4 | AD20: 0
A21: CUST00020 | B21: 46-60 | C21: South | D21: 1 | E21: 1 | F21: 1 | G21: Salary | H21: 14 | I21: 42484.840000000004 | J21: 3034.631428571429 | K21: 1 | L21: 4 | M21: 6 | N21: 8 | O21: 0 | P21: 0 | Q21: 0 | R21: 0 | S21: 1 | T21: 1 | U21: 1 | V21: 4 | W21: 19 | X21: Moderate | Y21: 1 | Z21: 1 | AA21: 46013 | AB21: 10 | AC21: 8 | AD21: 0
A22: CUST00021 | B22: 36-45 | C22: West | D22: 18 | E22: 1 | F22: 1 | G22: Savings | H22: 16 | I22: 28727.58 | J22: 1795.4738 | K22: 1 | L22: 8 | M22: 11 | N22: 6 | O22: 0 | P22: 0 | Q22: 0 | R22: 0 | S22: 1 | T22: 0 | U22: 0 | V22: 4 | W22: 26 | X22: High | Y22: 0 | Z22: 0 | AA22: 46021 | AB22: 2 | AC22: 10 | AD22: 0
A23: CUST00022 | B23: 18-25 | C23: West | D23: 24 | E23: 2 | F23: 2 | G23: Fixed Deposit, Savings | H23: 11 | I23: 31398.91 | J23: 2854.4463636363635 | K23: 2 | L23: 5 | M23: 9 | N23: 8 | O23: 0 | P23: 0 | Q23: 0 | R23: 0 | S23: 1 | T23: 1 | U23: 0 | V23: 4 | W23: 24 | X23: Moderate | Y23: 1 | Z23: 0 | AA23: 46017 | AB23: 6 | AC23: 1 | AD23: 0
A24: CUST00023 | B24: 26-35 | C24: West | D24: 3 | E24: 2 | F24: 1 | G24: Savings | H24: 22 | I24: 69972.07 | J24: 3180.548636363637 | K24: 1 | L24: 4 | M24: 10 | N24: 3 | O24: 0 | P24: 0 | Q24: 0 | R24: 0 | S24: 1 | T24: 0 | U24: 0 | V24: 4 | W24: 18 | X24: High | Y24: 0 | Z24: 0 | AA24: 46017 | AB24: 6 | AC24: 0 | AD24: 0
A25: CUST00024 | B25: 36-45 | C25: South | D25: 7 | E25: 2 | F25: 2 | G25: Current, Fixed Deposit | H25: 12 | I25: 43955.75 | J25: 3662.9791666666665 | K25: 3 | L25: 5 | M25: 16 | N25: 6 | O25: 0 | P25: 0 | Q25: 0 | R25: 0 | S25: 1 | T25: 0 | U25: 0 | V25: 4 | W25: 30 | X25: Moderate | Y25: 0 | Z25: 0 | AA25: 46001 | AB25: 22 | AC25: 2 | AD25: 0
A26: CUST00025 | B26: 60+ | C26: East | D26: 5 | E26: 1 | F26: 1 | G26: Salary | H26: 13 | I26: 23760.6 | J26: 1827.7384615384615 | K26: 4 | L26: 5 | M26: 15 | N26: 8 | O26: 0 | P26: 0 | Q26: 0 | R26: 0 | S26: 4 | T26: 0 | U26: 1 | V26: 4 | W26: 32 | X26: Moderate | Y26: 0 | Z26: 1 | AA26: 45992 | AB26: 31 | AC26: 3 | AD26: 0
A27: CUST00026 | B27: 36-45 | C27: North | D27: 25 | E27: 1 | F27: 1 | G27: Savings | H27: 16 | I27: 68616.83 | J27: 4288.5519 | K27: 3 | L27: 5 | M27: 15 | N27: 5 | O27: 0 | P27: 0 | Q27: 0 | R27: 0 | S27: 1 | T27: 0 | U27: 0 | V27: 4 | W27: 28 | X27: High | Y27: 0 | Z27: 0 | AA27: 45981 | AB27: 42 | AC27: -2 | AD27: 1
A28: CUST00027 | B28: 60+ | C28: North | D28: 15 | E28: 2 | F28: 2 | G28: Salary, Savings | H28: 8 | I28: 42040.33 | J28: 5255.0413 | K28: 1 | L28: 3 | M28: 15 | N28: 6 | O28: 0 | P28: 0 | Q28: 0 | R28: 0 | S28: 0 | T28: 0 | U28: 0 | V28: 4 | W28: 25 | X28: Moderate | Y28: 0 | Z28: 0 | AA28: 46017 | AB28: 6 | AC28: 2 | AD28: 0
A29: CUST00028 | B29: 18-25 | C29: West | D29: 3 | E29: 3 | F29: 2 | G29: Fixed Deposit, Savings | H29: 10 | I29: 32507.49 | J29: 3250.7490000000003 | K29: 2 | L29: 7 | M29: 11 | N29: 7 | O29: 0 | P29: 0 | Q29: 0 | R29: 0 | S29: 2 | T29: 1 | U29: 1 | V29: 4 | W29: 27 | X29: Moderate | Y29: 1 | Z29: 1 | AA29: 46010 | AB29: 13 | AC29: -4 | AD29: 1
A30: CUST00029 | B30: 18-25 | C30: Central | D30: 2 | E30: 2 | F30: 2 | G30: Fixed Deposit, Savings | H30: 15 | I30: 63339.56 | J30: 4222.637333333333 | K30: 5 | L30: 7 | M30: 10 | N30: 7 | O30: 0 | P30: 0 | Q30: 0 | R30: 0 | S30: 1 | T30: 0 | U30: 0 | V30: 4 | W30: 29 | X30: Moderate | Y30: 0 | Z30: 0 | AA30: 45955 | AB30: 68 | AC30: -3 | AD30: 1
A31: CUST00030 | B31: 26-35 | C31: South | D31: 20 | E31: 2 | F31: 2 | G31: Salary, Savings | H31: 27 | I31: 115889.53 | J31: 4292.204814814815 | K31: 2 | L31: 5 | M31: 15 | N31: 13 | O31: 0 | P31: 0 | Q31: 0 | R31: 0 | S31: 0 | T31: 0 | U31: 0 | V31: 4 | W31: 35 | X31: High | Y31: 0 | Z31: 0 | AA31: 45961 | AB31: 62 | AC31: -3 | AD31: 1
A32: CUST00031 | B32: 26-35 | C32: East | D32: 6 | E32: 2 | F32: 2 | G32: Current, Fixed Deposit | H32: 18 | I32: 46906.34 | J32: 2605.9077777777775 | K32: 4 | L32: 4 | M32: 17 | N32: 3 | O32: 0 | P32: 0 | Q32: 0 | R32: 0 | S32: 1 | T32: 0 | U32: 0 | V32: 4 | W32: 28 | X32: High | Y32: 0 | Z32: 0 | AA32: 46003 | AB32: 20 | AC32: 6 | AD32: 0
A33: CUST00032 | B33: 26-35 | C33: East | D33: 25 | E33: 1 | F33: 1 | G33: Current | H33: 23 | I33: 155436.45 | J33: 6758.106521739131 | K33: 2 | L33: 5 | M33: 7 | N33: 11 | O33: 0 | P33: 0 | Q33: 0 | R33: 0 | S33: 1 | T33: 1 | U33: 0 | V33: 4 | W33: 25 | X33: High | Y33: 1 | Z33: 0 | AA33: 46009 | AB33: 14 | AC33: 1 | AD33: 0
A34: CUST00033 | B34: 46-60 | C34: East | D34: 9 | E34: 1 | F34: 1 | G34: Savings | H34: 15 | I34: 27144.64 | J34: 1809.6426666666666 | K34: 0 | L34: 4 | M34: 10 | N34: 7 | O34: 0 | P34: 0 | Q34: 0 | R34: 1 | S34: 2 | T34: 0 | U34: 1 | V34: 3 | W34: 21 | X34: Moderate | Y34: 0 | Z34: 1 | AA34: 46017 | AB34: 6 | AC34: -1 | AD34: 1
A35: CUST00034 | B35: 26-35 | C35: Central | D35: 19 | E35: 1 | F35: 1 | G35: Current | H35: 28 | I35: 83092.01 | J35: 2967.5717857142854 | K35: 2 | L35: 6 | M35: 12 | N35: 11 | O35: 0 | P35: 0 | Q35: 0 | R35: 0 | S35: 1 | T35: 1 | U35: 0 | V35: 4 | W35: 31 | X35: High | Y35: 1 | Z35: 0 | AA35: 46019 | AB35: 4 | AC35: 2 | AD35: 0
A36: CUST00035 | B36: 36-45 | C36: West | D36: 14 | E36: 1 | F36: 1 | G36: Savings | H36: 14 | I36: 23005.94 | J36: 1643.2814285714285 | K36: 0 | L36: 4 | M36: 10 | N36: 9 | O36: 0 | P36: 0 | Q36: 0 | R36: 0 | S36: 0 | T36: 0 | U36: 0 | V36: 3 | W36: 23 | X36: Moderate | Y36: 0 | Z36: 0 | AA36: 46016 | AB36: 7 | AC36: 0 | AD36: 0
A37: CUST00036 | B37: 26-35 | C37: Central | D37: 6 | E37: 2 | F37: 1 | G37: Savings | H37: 22 | I37: 74582.72 | J37: 3390.1236363636363 | K37: 6 | L37: 9 | M37: 6 | N37: 9 | O37: 0 | P37: 0 | Q37: 0 | R37: 0 | S37: 1 | T37: 1 | U37: 0 | V37: 4 | W37: 30 | X37: High | Y37: 1 | Z37: 0 | AA37: 46011 | AB37: 12 | AC37: -6 | AD37: 1
A38: CUST00037 | B38: 60+ | C38: West | D38: 25 | E38: 1 | F38: 1 | G38: Savings | H38: 12 | I38: 68744.93000000001 | J38: 5728.744166666667 | K38: 1 | L38: 7 | M38: 9 | N38: 12 | O38: 0 | P38: 0 | Q38: 0 | R38: 0 | S38: 0 | T38: 0 | U38: 0 | V38: 4 | W38: 29 | X38: Moderate | Y38: 0 | Z38: 0 | AA38: 46016 | AB38: 7 | AC38: -2 | AD38: 1
A39: CUST00038 | B39: 18-25 | C39: South | D39: 7 | E39: 2 | F39: 2 | G39: Fixed Deposit, Savings | H39: 15 | I39: 24312.28 | J39: 1620.8186666666666 | K39: 2 | L39: 6 | M39: 8 | N39: 15 | O39: 0 | P39: 0 | Q39: 0 | R39: 0 | S39: 3 | T39: 2 | U39: 1 | V39: 4 | W39: 31 | X39: Moderate | Y39: 1 | Z39: 1 | AA39: 46019 | AB39: 4 | AC39: 11 | AD39: 0
A40: CUST00039 | B40: 18-25 | C40: North | D40: 15 | E40: 1 | F40: 1 | G40: Savings | H40: 16 | I40: 43209.25 | J40: 2700.5781 | K40: 1 | L40: 4 | M40: 8 | N40: 5 | O40: 0 | P40: 0 | Q40: 0 | R40: 0 | S40: 1 | T40: 0 | U40: 0 | V40: 4 | W40: 18 | X40: High | Y40: 0 | Z40: 0 | AA40: 46015 | AB40: 8 | AC40: -2 | AD40: 1
...

Sheet Pivot_Analysis_2
A1: Balance Distribution by Age Band
A3: Count of account_id | B3: balance_band
A4: age_band | B4: 0-10K | C4: 100K-500K | D4: 10K-50K | E4: 500K+ | F4: 50K-100K | G4: Grand Total
A5: 18-25 | B5: 49 | C5: 58 | D5: 71 | E5: 12 | F5: 49 | G5: 239
A6: 26-35 | B6: 75 | C6: 100 | D6: 146 | E6: 37 | F6: 107 | G6: 465
A7: 36-45 | B7: 81 | C7: 89 | D7: 119 | E7: 29 | F7: 77 | G7: 395
A8: 46-60 | B8: 61 | C8: 85 | D8: 106 | E8: 33 | F8: 61 | G8: 346
A9: 60+ | B9: 32 | C9: 41 | D9: 65 | E9: 21 | F9: 37 | G9: 196
A10: Grand Total | B10: 298 | C10: 373 | D10: 507 | E10: 132 | F10: 331 | G10: 1641

Sheet Account_Data
A1: account_id | B1: customer_id | C1: account_type | D1: balance_band | E1: age_band
A2: ACC000001 | B2: CUST00001 | C2: Savings | D2: 100K-500K | E2: =VLOOKUP(B2,Customer_Data!$A:$C,2,FALSE) -> 36-45
A3: ACC000002 | B3: CUST00002 | C3: Savings | D3: 100K-500K | E3: =VLOOKUP(B3,Customer_Data!$A:$C,2,FALSE) -> 46-60
A4: ACC000003 | B4: CUST00003 | C4: Savings | D4: 500K+ | E4: =VLOOKUP(B4,Customer_Data!$A:$C,2,FALSE) -> 60+
A5: ACC000004 | B5: CUST00004 | C5: Current | D5: 10K-50K | E5: =VLOOKUP(B5,Customer_Data!$A:$C,2,FALSE) -> 60+
A6: ACC000005 | B6: CUST00005 | C6: Current | D6: 50K-100K | E6: =VLOOKUP(B6,Customer_Data!$A:$C,2,FALSE) -> 26-35
A7: ACC000006 | B7: CUST00006 | C7: Savings | D7: 0-10K | E7: =VLOOKUP(B7,Customer_Data!$A:$C,2,FALSE) -> 36-45
A8: ACC000007 | B8: CUST00006 | C8: Savings | D8: 500K+ | E8: =VLOOKUP(B8,Customer_Data!$A:$C,2,FALSE) -> 36-45
A9: ACC000008 | B9: CUST00006 | C9: Salary | D9: 50K-100K | E9: =VLOOKUP(B9,Customer_Data!$A:$C,2,FALSE) -> 36-45
A10: ACC000009 | B10: CUST00007 | C10: Salary | D10: 10K-50K | E10: =VLOOKUP(B10,Customer_Data!$A:$C,2,FALSE) -> 26-35
A11: ACC000010 | B11: CUST00008 | C11: Current | D11: 0-10K | E11: =VLOOKUP(B11,Customer_Data!$A:$C,2,FALSE) -> 46-60
A12: ACC000011 | B12: CUST00008 | C12: Fixed Deposit | D12: 100K-500K | E12: =VLOOKUP(B12,Customer_Data!$A:$C,2,FALSE) -> 46-60
A13: ACC000012 | B13: CUST00009 | C13: Savings | D13: 10K-50K | E13: =VLOOKUP(B13,Customer_Data!$A:$C,2,FALSE) -> 36-45
... A1642: ACC001641 | B1642: CUST01200 | C1642: Savings | D1642: 100K-500K | E1642: =VLOOKUP(B1642,Customer_Data!$A:$C,2,FALSE) -> 60+

Sheet Transaction_Data
A1: transaction_id | B1: customer_id | C1: account_id | D1: transaction_date | E1: amount | F1: transaction_type | G1: period
A2: TXN00000001 | B2: CUST00001 | C2: ACC000001 | D2: 45869 | E2: 3793.1 | F2: Transfer | G2: H2
A3: TXN00000002 | B3: CUST00001 | C3: ACC000001 | D3: 45778 | E3: 4284.16 | F3: Transfer | G3: H1
A4: TXN00000003 | B4: CUST00001 | C4: ACC000001 | D4: 45841 | E4: 1604.08 | F4: Transfer | G4: H2
A5: TXN00000004 | B5: CUST00001 | C5: ACC000001 | D5: 45795 | E5: 5664.84 | F5: Debit | G5: H1
A6: TXN00000005 | B6: CUST00001 | C6: ACC000001 | D6: 45942 | E6: 1740.3 | F6: Debit | G6: H2
A7: TXN00000006 | B7: CUST00001 | C7: ACC000001 | D7: 45718 | E7: 1221.64 | F7: Bill Payment | G7: H1
A8: TXN00000007 | B8: CUST00001 | C8: ACC000001 | D8: 45677 | E8: 382.15 | F8: Credit | G8: H1
A9: TXN00000008 | B9: CUST00001 | C9: ACC000001 | D9: 45694 | E9: 1129.63 | F9: Transfer | G9: H1
A10: TXN00000009 | B10: CUST00001 | C10: ACC000001 | D10: 45794 | E10: 420.82 | F10: Debit | G10: H1
A11: TXN00000010 | B11: CUST00001 | C11: ACC000001 | D11: 45787 | E11: 224.46 | F11: Credit | G11: H1
A12: TXN00000011 | B12: CUST00001 | C12: ACC000001 | D12: 45821 | E12: 608 | F12: Bill Payment | G12: H1
A13: TXN00000012 | B13: CUST00001 | C13: ACC000001 | D13: 45791 | E13: 6284.5 | F13: Credit | G13: H1
... A11425: TXN00011424 | B11425: CUST00627 | C11425: ACC000879 | D11425: 45894 | E11425: 9089.99 | F11425: Bill Payment | G11425: H2
A11426: TXN00011425 | B11426: CUST00627 | C11426: ACC000879 | D11426: 45970 | E11426: 147109.59999999998 | F11426: Credit | G11426: H2
A11427: TXN00011426 | B11427: CUST00627 | C11427: ACC000879 | D11427: 45884 | E11427: 1329.35 | F11427: Transfer | G11427: H2
A11428: TXN00011427 | B11428: CUST00627 | C11428: ACC000879 | D11428: 45926 | E11428: 6640.56 | F11428: Credit | G11428: H2
A11429: TXN00011428 | B11429: CUST00627 | C11429: ACC000879 | D11429: 45847 | E11429: 380.72 | F11429: Bill Payment | G11429: H2
A11430: TXN00011429 | B11430: CUST00627 | C11430: ACC000879 | D11430: 45782 | E11430: 22721.25 | F11430: Transfer | G11430: H1
A11431: TXN00011430 | B11431: CUST00628 | C11431: ACC000880 | D11431: 45709 | E11431: 5540.45 | F11431: Transfer | G11431: H1
A11432: TXN00011431 | B11432: CUST00628 | C11432: ACC000880 | D11432: 45670 | E11432: 272.9 | F11432: Debit | G11432: H1
A11433: TXN00011432 | B11433: CUST00628 | C11433: ACC000880 | D11433: 45974 | E11433: 3931.85 | F11433: Credit | G11433: H2
A11434: TXN00011433 | B11434: CUST00628 | C11434: ACC000880 | D11434: 45857 | E11434: 1014.38 | F11434: Bill Payment | G11434: H2
A11435: TXN00011434 | B11435: CUST00628 | C11435: ACC000880 | D11435: 45990 | E11435: 1299.41 | F11435: Bill Payment | G11435: H2
A11436: TXN00011435 | B11436: CUST00628 | C11436: ACC000880 | D11436: 45695 | E11436: 8763.15 | F11436: Bill Payment | G11436: H1
A11437: TXN00011436 | B11437: CUST00628 | C11437: ACC000880 | D11437: 45717 | E11437: 612.16 | F11437: Credit | G11437: H1
A11438: TXN00011437 | B11438: CUST00628 | C11438: ACC000880 | D11438: 45856 | E11438: 839.34 | F11438: Debit | G11438: H2
... A12878: TXN00012877 | B12878: CUST00706 | C12878: ACC000987 | D12878: 45778 | E12878: 503.95 | F12878: Credit | G12878: H1
A12879: TXN00012878 | B12879: CUST00706 | C12879: ACC000987 | D12879: 45797 | E12879: 88615.20000000001 | F12879: Transfer | G12879: H1
A12880: TXN00012879 | B12880: CUST00707 | C12880: ACC000988 | D12880: 45858 | E12880: 716.89 | F12880: Debit | G12880: H2
A12881: TXN00012880 | B12881: CUST00707 | C12881: ACC000988 | D12881: 45815 | E12881: 3190.09 | F12881: Credit | G12881: H1
A12882: TXN00012881 | B12882: CUST00707 | C12882: ACC000988 | D12882: 45719 | E12882: 3970.4 | F12882: Debit | G12882: H1
A12883: TXN00012882 | B12883: CUST00707 | C12883: ACC000988 | D12883: 45958 | E12883: 5560.12 | F12883: Transfer | G12883: H2
A12884: TXN00012883 | B12884: CUST00707 | C12884: ACC000988 | D12884: 45813 | E12884: 6007.29 | F12884: Credit | G12884: H1
A12885: TXN00012884 | B12885: CUST00707 | C12885: ACC000988 | D12885: 45942 | E12885: 1833.23 | F12885: Transfer | G12885: H2
A12886: TXN00012885 | B12886: CUST00707 | C12886: ACC000988 | D12886: 45905 | E12886: 7618.81 | F12886: Debit | G12886: H2
A12887: TXN00012886 | B12887: CUST00707 | C12887: ACC000988 | D12887: 45832 | E12887: 1669.61 | F12887: Debit | G12887: H1
A12888: TXN00012887 | B12888: CUST00707 | C12888: ACC000988 | D12888: 45808 | E12888: 607.89 | F12888: Debit | G12888: H1
A12889: TXN00012888 | B12889: CUST00707 | C12889: ACC000988 | D12889: 45887 | E12889: 602.94 | F12889: Credit | G12889: H2
A12890: TXN00012889 | B12890: CUST00707 | C12890: ACC000988 | D12890: 45795 | E12890: 365.3 | F12890: Debit | G12890: H1
...

Sheet Pivot_Analysis_1
A1: Complaint Analysis by Region
A3: Count of service_id | B3: complaint_flag
A4: region | B4: No | C4: Unknown | D4: Yes | E4: Grand Total
A5: Central | B5: 153 | C5: 18 | D5: 67 | E5: 238
A6: East | B6: 158 | C6: 12 | D6: 71 | E6: 241
A7: North | B7: 156 | C7: 18 | D7: 64 | E7: 238
A8: South | B8: 201 | C8: 22 | D8: 89 | E8: 312
A9: West | B9: 221 | C9: 24 | D9: 82 | E9: 327
A10: Grand Total | B10: 889 | C10: 94 | D10: 373 | E10: 1356
A32: Service Request Trends
A35: request_type | B35: Count of service_id
A36: Account Update | B36: 211
A37: Card Issue | B37: 227
A38: Digital Banking | B38: 224
A39: Loan Query | B39: 229
A40: Other | B40: 229
A41: Transaction Dispute | B41: 236
A42: Grand Total | B42: 1356

Sheet Service_Data
A1: service_id | B1: customer_id | C1: request_type | D1: complaint_flag | E1: resolution | F1: service_date | G1: is_complaint | H1: is_unresolved | I1: region
A2: SRV0000001 | B2: CUST00001 | C2: Loan Query | D2: No | E2: Resolved | F2: 46001 | G2: 0 | H2: 0 | I2: =VLOOKUP(B2,Customer_Data!$A:$C,3,FALSE) -> South
A3: SRV0000002 | B3: CUST00002 | C3: Account Update | D3: No | E3: Resolved | F3: 45822 | G3: 0 | H3: 0 | I3: =VLOOKUP(B2,Customer_Data!$A:$C,3,FALSE) -> South
A4: SRV0000003 | B4: CUST00003 | C4: Card Issue | D4: Yes | E4: Resolved | F4: 45727 | G4: 1 | H4: 0 | I4: =VLOOKUP(B2,Customer_Data!$A:$C,3,FALSE) -> South
A5: SRV0000004 | B5: CUST00004 | C5: Loan Query | D5: Yes | E5: Resolved | F5: 45825 | G5: 1 | H5: 0 | I5: =VLOOKUP(B2,Customer_Data!$A:$C,3,FALSE) -> South
A6: SRV0000005 | B6: CUST00004 | C6: Transaction Dispute | D6: No | E6: Resolved | F6: 45760 | G6: 0 | H6: 0 | I6: =VLOOKUP(B2,Customer_Data!$A:$C,3,FALSE) -> South
A7: SRV0000006 | B7: CUST00005 | C7: Account Update | D7: No | E7: Resolved | F7: 45723 | G7: 0 | H7: 0 | I7: =VLOOKUP(B2,Customer_Data!$A:$C,3,FALSE) -> South
A8: SRV0000007 | B8: CUST00006 | C8: Other | D8: Yes | E8: Resolved | F8: 45939 | G8: 1 | H8: 0 | I8: =VLOOKUP(B3,Customer_Data!$A:$C,3,FALSE) -> West
A9: SRV0000008 | B9: CUST00006 | C9: Other | D9: Yes | E9: Resolved | F9: 45966 | G9: 1 | H9: 0 | I9: =VLOOKUP(B4,Customer_Data!$A:$C,3,FALSE) -> Central
A10: SRV0000009 | B10: CUST00008 | C10: Account Update | D10: No | E10: Resolved | F10: 45929 | G10: 0 | H10: 0 | I10: =VLOOKUP(B5,Customer_Data!$A:$C,3,FALSE) -> West
A11: SRV0000010 | B11: CUST00010 | C11: Digital Banking | D11: Yes | E11: Resolved | F11: 45828 | G11: 1 | H11: 0 | I11: =VLOOKUP(B6,Customer_Data!$A:$C,3,FALSE) -> West
A12: SRV0000011 | B12: CUST00010 | C12: Card Issue | D12: No | E12: Resolved | F12: 45938 | G12: 0 | H12: 0 | I12: =VLOOKUP(B7,Customer_Data!$A:$C,3,FALSE) -> West
A13: SRV0000012 | B13: CUST00012 | C13: Digital Banking | D13: No | E13: Resolved | F13: 45701 | G13: 0 | H13: 0 | I13: =VLOOKUP(B8,Customer_Data!$A:$C,3,FALSE) -> East
A14: SRV0000013 | B14: CUST00013 | C14: Digital Banking | D14: No | E14: Resolved | F14: 45813 | G14: 0 | H14: 0 | I14: =VLOOKUP(B9,Customer_Data!$A:$C,3,FALSE) -> East
A15: SRV0000014 | B15: CUST00014 | C15: Transaction Dispute | D15: Unknown | E15: Resolved | F15: 45662 | G15: 0 | H15: 0 | I15: =VLOOKUP(B10,Customer_Data!$A:$C,3,FALSE) -> West
A16: SRV0000015 | B16: CUST00016 | C16: Loan Query | D16: No | E16: Resolved | F16: 45705 | G16: 0 | H16: 0 | I16: =VLOOKUP(B11,Customer_Data!$A:$C,3,FALSE) -> South
A17: SRV0000016 | B17: CUST00016 | C17: Transaction Dispute | D17: No | E17: Resolved | F17: 45806 | G17: 0 | H17: 0 | I17: =VLOOKUP(B12,Customer_Data!$A:$C,3,FALSE) -> South
A18: SRV0000017 | B18: CUST00017 | C18: Loan Query | D18: Yes | E18: Pending | F18: 45831 | G18: 1 | H18: 1 | I18: =VLOOKUP(B13,Customer_Data!$A:$C,3,FALSE) -> Central
... A1357: SRV0001356 | B1357: CUST01197 | C1357: Transaction Dispute | D1357: No | E1357: Resolved | F1357: 45945 | G1357: 0 | H1357: 0 | I1357: =VLOOKUP(B1352,Customer_Data!$A:$C,3,FALSE) -> West

Sheet summary
A2: Channel | B2: Total Usage
A3: Branch Visits | B3: =SUM(Customer_Data!K2:K1201) -> 2635
A4: Atm Usage | B4: =SUM(Customer_Data!L2:L1201) -> 5948
A5: Mobile Usage | B5: =SUM(Customer_Data!M2:M1201) -> 13012
A6: Internet Usage | B6: =SUM(Customer_Data!N2:N1201) -> 8369
